const main = () => {
    try {
        erro
    } catch (err) {
        console.log(`esse Ã© o erro ${err}`)
    } finally {
        console.log('testando')
    }
}

main()